Workbook

Sheet Start here
B2: Full-body strength tracker – 6 days
B3: Performance across every movement pattern. Yellow cells with blue text are the only ones you type in (plus the log sheets).
B5: Program start date (a Monday) | C5: 46307 | D5: Change to your real first Monday.
B6: Week override (optional) | D6: Type a week number if you fall behind; leave blank to follow the calendar.
B7: THIS WEEK
B8: Week # | C8: =IF(C6<>"",C6,MAX(1,INT((TODAY()-C5)/7)+1)) -> 1
B9: Phase | C9: =IFERROR(INDEX(Plan!$C$2:$C$32,MATCH($C$8,Plan!$A$2:$A$32,0)),"Beyond plan: extend Plan") -> Ramp
B10: Block week | C10: =IFERROR(INDEX(Plan!$D$2:$D$32,MATCH($C$8,Plan!$A$2:$A$32,0)),"") -> 1
B11: Saturday session | C11: =IFERROR(INDEX(Plan!$K$2:$K$32,MATCH($C$8,Plan!$A$2:$A$32,0)),"") -> A
B12: Main lifts: top set | C12: =IFERROR(INDEX(Plan!$G$2:$G$32,MATCH($C$8,Plan!$A$2:$A$32,0))&" reps @RPE "&INDEX(Plan!$H$2:$H$32,MATCH($C$8,Plan!$A$2:$A$32,0)),"") -> 5 reps @RPE 6
B13: Volume % | C13: =IFERROR(INDEX(Plan!$E$2:$E$32,MATCH($C$8,Plan!$A$2:$A$32,0)),"") -> 0.5
B14: Accessory RPE cap | C14: =IFERROR(INDEX(Plan!$F$2:$F$32,MATCH($C$8,Plan!$A$2:$A$32,0)),"") -> 6
B15: Back-off sets | C15: =IFERROR(INDEX(Plan!$J$2:$J$32,MATCH($C$8,Plan!$A$2:$A$32,0))&" at "&TEXT(INDEX(Plan!$I$2:$I$32,MATCH($C$8,Plan!$A$2:$A$32,0)),"0%")&" below the top set","") -> 3 × 5 at 10% below the top set
B16: Note | C16: =IFERROR(INDEX(Plan!$L$2:$L$32,MATCH($C$8,Plan!$A$2:$A$32,0))&"","") -> Re-learn the lifts. New risky work: 1 set (see Entry ramps).
B17: Elbow variants | C17: =IF(LEFT(C9,5)="Block",IF(ISODD(VALUE(RIGHT(C9,1))),"Odd-block list","Even-block list"),"Odd-block list") -> Odd-block list
B19: WEEK AT A GLANCE
B20: Day | C20: Focus | D20: Base sets | E20: Sets this week | F20: Kung fu that night? | H20: Key rule
B21: Mon | C21: Squat + anterior trunk | D21: =SUMIFS(Program!$F$2:$F$75,Program!$A$2:$A$75,"Mon") -> 20 | E21: =SUMIFS(Program!$N$2:$N$75,Program!$A$2:$A$75,"Mon") -> 12 | F21: Yes | H21: Squat top set capped at RPE 8.
B22: Tue | C22: Horizontal push / pull + heavy carry | D22: =SUMIFS(Program!$F$2:$F$75,Program!$A$2:$A$75,"Tue") -> 22 | E22: =SUMIFS(Program!$N$2:$N$75,Program!$A$2:$A$75,"Tue") -> 12 | F22: Yes
B23: Wed | C23: Single-leg, frontal plane, trunk, neck | D23: =SUMIFS(Program!$F$2:$F$75,Program!$A$2:$A$75,"Wed") -> 23 | E23: =SUMIFS(Program!$N$2:$N$75,Program!$A$2:$A$75,"Wed") -> 12 | F23: Yes | H23: Keep everything RPE ≤7.
B24: Thu | C24: Vertical push / pull + shoulders | D24: =SUMIFS(Program!$F$2:$F$75,Program!$A$2:$A$75,"Thu") -> 22 | E24: =SUMIFS(Program!$N$2:$N$75,Program!$A$2:$A$75,"Thu") -> 12 | F24: Yes
B25: Fri | C25: Hinge + knees + calves | D25: =SUMIFS(Program!$F$2:$F$75,Program!$A$2:$A$75,"Fri") -> 21 | E25: =SUMIFS(Program!$N$2:$N$75,Program!$A$2:$A$75,"Fri") -> 12 | F25: No | H25: Heaviest day: no class tonight.
B26: Sat A | C26: Front squat + hips, elbows, wrist | D26: =SUMIFS(Program!$F$2:$F$75,Program!$A$2:$A$75,"Sat",Program!$B$2:$B$75,"All")+SUMIFS(Program!$F$2:$F$75,Program!$A$2:$A$75,"Sat",Program!$B$2:$B$75,"A") -> 23 | E26: =SUMIFS(Program!$N$2:$N$75,Program!$A$2:$A$75,"Sat",Program!$B$2:$B$75,"All")+SUMIFS(Program!$N$2:$N$75,Program!$A$2:$A$75,"Sat",Program!$B$2:$B$75,"A") -> 13 | F26: No | H26: Odd weeks.
B27: Sat B | C27: Front squat + spine, scapula, grip | D27: =SUMIFS(Program!$F$2:$F$75,Program!$A$2:$A$75,"Sat",Program!$B$2:$B$75,"All")+SUMIFS(Program!$F$2:$F$75,Program!$A$2:$A$75,"Sat",Program!$B$2:$B$75,"B") -> 23 | E27: =SUMIFS(Program!$N$2:$N$75,Program!$A$2:$A$75,"Sat",Program!$B$2:$B$75,"All")+SUMIFS(Program!$N$2:$N$75,Program!$A$2:$A$75,"Sat",Program!$B$2:$B$75,"B") -> 13 | F27: No | H27: Even weeks.
B28: Home | C28: Neck rotation, hands, feet (≈10 min) | D28: =SUMIFS(Program!$F$2:$F$75,Program!$A$2:$A$75,"Home") -> 20 | E28: =SUMIFS(Program!$N$2:$N$75,Program!$A$2:$A$75,"Home") -> 20 | F28: – | H28: Twice a week, e.g. Tue + Sun.
B29: Gym sets per week (Mon–Fri + one Saturday) | D29: =SUM(D21:D25)+D26 -> 131 | E29: =SUM(E21:E25)+IF(C11="B",E27,E26) -> 73
B30: Expect roughly 60–75 min per gym session at full volume. Sunday is off (home routine is fine).
B32: HOW TO USE IT
B33: 1. Set the start date above. 'This week' then tells you the phase, Saturday type, main-lift target and volume.
B34: 2. Train from Program. 'Sets this week' already scales for the ramp and deloads.
B35: 3. Main lifts: check 'Next session' at the top of Main lifts, then log the top set (kg, reps, RPE). It works out e1RM and flags drops.
B36: 4. Everything else: log in Accessory log. It tells you when to add load, and how many reps you need before a big weight jump.
B37: 5. Before each session, score readiness in Readiness (10 seconds). It tells you whether to train as planned or cut back.
B38: 6. Weeks 1 and 11 of each block: run the Tests sheet for the small joints.
B39: 7. New risky exercises (neck, dips, reverse Nordic, Copenhagen, hip rotation) follow Entry ramps for the first 6 weeks.
B41: RULES
B42: Main lifts | C42: Top set at the Plan's reps and RPE, then back-off sets at the Plan's % below it. Top set ≥1 RPE above target: cut back-offs 5%. ≥1 below: add 2.5 kg (upper) or 5 kg (lower) to back-offs.
B43: e1RM | C43: e1RM = load × (1 + (reps + reps-in-reserve) / 30), where reps-in-reserve = 10 − RPE. Valid up to about 10 total. A true single at RPE 10 is just the load.
B44: Accessories | C44: Double progression: when every set reaches the top of the range at RIR ≤2, add the smallest step. Below the bottom of the range twice: drop 5–10%.
B45: Big jumps | C45: When the next weight is >10% heavier (e.g. 7.5 → 10 kg), stay until you can do the reps the Accessory log shows, or use fractional plates.
...

Sheet Program
A1: Day | B1: Week | C1: # | D1: Exercise | E1: What it covers | F1: Base sets | G1: Reps / time | H1: Range low | I1: Range high | J1: Effort | K1: Progression | L1: Priority this block? (Y) | M1: Sets this block | N1: Sets this week | O1: Notes
A2: Mon | B2: All | C2: 1 | D2: Back squat | E2: Squat; knee extension; hip extension | F2: 4 | G2: Wave (see Plan) | J2: Wave RPE; cap 8 on class nights | K2: Main lift | M2: =IF(UPPER(L2)="Y",F2+2,F2) -> 4 | N2: =IF(A2="Home",M2,IF('Start here'!$C$13="",M2,MAX(1,ROUND(M2*'Start here'!$C$13,0)))) -> 2 | O2: Top set, then 3 back-off sets at the Plan's % off. Use the Main lifts calculator.
A3: Mon | B3: All | C3: 2 | D3: Seated leg curl | E3: Knee flexion, hip flexed | F3: 3 | G3: 8–12 | H3: 8 | I3: 12 | J3: RIR 1–2 | K3: Double progression | M3: =IF(UPPER(L3)="Y",F3+2,F3) -> 3 | N3: =IF(A3="Home",M3,IF('Start here'!$C$13="",M3,MAX(1,ROUND(M3*'Start here'!$C$13,0)))) -> 2
A4: Mon | B4: All | C4: 3 | D4: Seated calf raise | E4: Plantar flexion, knee bent (soleus) | F4: 3 | G4: 12–15 | H4: 12 | I4: 15 | J4: RIR 1–2 | K4: Double progression | M4: =IF(UPPER(L4)="Y",F4+2,F4) -> 3 | N4: =IF(A4="Home",M4,IF('Start here'!$C$13="",M4,MAX(1,ROUND(M4*'Start here'!$C$13,0)))) -> 2 | O4: Pause 1 s at the bottom.
A5: Mon | B5: All | C5: 4 | D5: Cable dorsiflexion | E5: Ankle dorsiflexion (tibialis) | F5: 2 | G5: 12–20 | H5: 12 | I5: 20 | J5: RIR 2 | K5: Double progression | M5: =IF(UPPER(L5)="Y",F5+2,F5) -> 2 | N5: =IF(A5="Home",M5,IF('Start here'!$C$13="",M5,MAX(1,ROUND(M5*'Start here'!$C$13,0)))) -> 1 | O5: Ankle strap on a low pulley. No strap: dumbbell between the feet, seated on a bench edge.
A6: Mon | B6: All | C6: 5 | D6: Hanging leg raise (pelvis curls up) | E6: Hip flexion knee straight; posterior pelvic tilt; spinal flexion | F6: 3 | G6: 6–12 | H6: 6 | I6: 12 | J6: RIR 2 | K6: Double progression | M6: =IF(UPPER(L6)="Y",F6+2,F6) -> 3 | N6: =IF(A6="Home",M6,IF('Start here'!$C$13="",M6,MAX(1,ROUND(M6*'Start here'!$C$13,0)))) -> 2 | O6: Only counts for pelvic tilt if the pelvis curls up at the top. Add a dumbbell between the feet once 12 is easy.
A7: Mon | B7: All | C7: 6 | D7: Ab rollout (from knees) | E7: Anti-extension | F7: 3 | G7: 6–10 | H7: 6 | I7: 10 | J7: RIR 2 | K7: Double progression (range, then standing) | M7: =IF(UPPER(L7)="Y",F7+2,F7) -> 3 | N7: =IF(A7="Home",M7,IF('Start here'!$C$13="",M7,MAX(1,ROUND(M7*'Start here'!$C$13,0)))) -> 2 | O7: Partial range weeks 1–4.
A8: Mon | B8: All | C8: 7 | D8: Cable crunch | E8: Spinal flexion | F8: 2 | G8: 10–15 | H8: 10 | I8: 15 | J8: RIR 1–2 | K8: Double progression | M8: =IF(UPPER(L8)="Y",F8+2,F8) -> 2 | N8: =IF(A8="Home",M8,IF('Start here'!$C$13="",M8,MAX(1,ROUND(M8*'Start here'!$C$13,0)))) -> 1
A9: Tue | B9: All | C9: 1 | D9: Bench press | E9: Horizontal push; horizontal adduction; elbow extension | F9: 4 | G9: Wave (see Plan) | J9: Wave RPE | K9: Main lift | M9: =IF(UPPER(L9)="Y",F9+2,F9) -> 4 | N9: =IF(A9="Home",M9,IF('Start here'!$C$13="",M9,MAX(1,ROUND(M9*'Start here'!$C$13,0)))) -> 2 | O9: Top set + 3 back-off sets.
A10: Tue | B10: All | C10: 2 | D10: Chest-supported row | E10: Horizontal pull; scapular retraction | F10: 4 | G10: 6–8 | H10: 6 | I10: 8 | J10: RIR 1–2 | K10: Double progression | M10: =IF(UPPER(L10)="Y",F10+2,F10) -> 4 | N10: =IF(A10="Home",M10,IF('Start here'!$C$13="",M10,MAX(1,ROUND(M10*'Start here'!$C$13,0)))) -> 2 | O10: Straps allowed, to spare grip.
A11: Tue | B11: All | C11: 3 | D11: Seated DB overhead press | E11: Vertical push (2nd exposure); shoulder flexion | F11: 3 | G11: 6–8 | H11: 6 | I11: 8 | J11: RIR 2 | K11: Double progression | M11: =IF(UPPER(L11)="Y",F11+2,F11) -> 3 | N11: =IF(A11="Home",M11,IF('Start here'!$C$13="",M11,MAX(1,ROUND(M11*'Start here'!$C$13,0)))) -> 2
A12: Tue | B12: All | C12: 4 | D12: Dip | E12: Decline push; scapular downward rotation | F12: 3 | G12: 6–10 | H12: 6 | I12: 10 | J12: RIR 2 | K12: Double progression (then add kg) | M12: =IF(UPPER(L12)="Y",F12+2,F12) -> 3 | N12: =IF(A12="Home",M12,IF('Start here'!$C$13="",M12,MAX(1,ROUND(M12*'Start here'!$C$13,0)))) -> 2 | O12: Bodyweight weeks 1–4; stop when the upper arm is parallel to the floor. See Entry ramps.
A13: Tue | B13: All | C13: 5 | D13: Reverse fly (cable or rear-delt machine) | E13: Shoulder horizontal abduction; scapular retraction | F13: 2 | G13: 12–15 | H13: 12 | I13: 15 | J13: RIR 1–2 | K13: Double progression | M13: =IF(UPPER(L13)="Y",F13+2,F13) -> 2 | N13: =IF(A13="Home",M13,IF('Start here'!$C$13="",M13,MAX(1,ROUND(M13*'Start here'!$C$13,0)))) -> 1
A14: Tue | B14: All | C14: 6 | D14: Elbow flexion – Tue slot | E14: Odd blocks: EZ curl (supinated). Even blocks: preacher curl (arm in front) | F14: 2 | G14: 8–12 | H14: 8 | I14: 12 | J14: RIR 1–2 | K14: Double progression | M14: =IF(UPPER(L14)="Y",F14+2,F14) -> 2 | N14: =IF(A14="Home",M14,IF('Start here'!$C$13="",M14,MAX(1,ROUND(M14*'Start here'!$C$13,0)))) -> 1 | O14: Block = 12-week block in Plan. The ramp counts as odd.
A15: Tue | B15: All | C15: 7 | D15: Elbow extension – Tue slot | E15: Odd blocks: skull crusher (arm in front). Even blocks: overhead cable extension | F15: 2 | G15: 8–12 | H15: 8 | I15: 12 | J15: RIR 1–2 | K15: Double progression | M15: =IF(UPPER(L15)="Y",F15+2,F15) -> 2 | N15: =IF(A15="Home",M15,IF('Start here'!$C$13="",M15,MAX(1,ROUND(M15*'Start here'!$C$13,0)))) -> 1 | O15: Superset with the curl slot.
A16: Tue | B16: All | C16: 8 | D16: Farmer carry (heavy) | E16: Two-hand carry; support grip; anti-flexion | F16: 2 | G16: 20–30 m | H16: 20 | I16: 30 | J16: Hard but clean posture | K16: Carry: hit 30 m, then add load | M16: =IF(UPPER(L16)="Y",F16+2,F16) -> 2 | N16: =IF(A16="Home",M16,IF('Start here'!$C$13="",M16,MAX(1,ROUND(M16*'Start here'!$C$13,0)))) -> 1 | O16: Out-and-back 10–15 m if there's no lane. Kept off Friday to separate grip days.
A17: Wed | B17: All | C17: 1 | D17: Bulgarian split squat | E17: Lunge / split squat; single leg | F17: 3 | G17: 6–8 / side | H17: 6 | I17: 8 | J17: RPE ≤7 (class night) | K17: Double progression | M17: =IF(UPPER(L17)="Y",F17+2,F17) -> 3 | N17: =IF(A17="Home",M17,IF('Start here'!$C$13="",M17,MAX(1,ROUND(M17*'Start here'!$C$13,0)))) -> 2 | O17: Wednesday stays easy: leaves something for kicking that night.
A18: Wed | B18: All | C18: 2 | D18: Single-leg RDL | E18: Single-leg hinge | F18: 2 | G18: 6–10 / side | H18: 6 | I18: 10 | J18: RPE ≤7 | K18: Double progression | M18: =IF(UPPER(L18)="Y",F18+2,F18) -> 2 | N18: =IF(A18="Home",M18,IF('Start here'!$C$13="",M18,MAX(1,ROUND(M18*'Start here'!$C$13,0)))) -> 1
A19: Wed | B19: All | C19: 3 | D19: Cossack squat | E19: Lateral lunge (frontal plane); hip adduction | F19: 2 | G19: 6–8 / side | H19: 6 | I19: 8 | J19: RPE ≤7 | K19: Double progression | M19: =IF(UPPER(L19)="Y",F19+2,F19) -> 2 | N19: =IF(A19="Home",M19,IF('Start here'!$C$13="",M19,MAX(1,ROUND(M19*'Start here'!$C$13,0)))) -> 1 | O19: Bodyweight weeks 1–4, then goblet.
A20: Wed | B20: All | C20: 4 | D20: Copenhagen plank | E20: Hip adduction, hip extended; anti-lateral flexion | F20: 2 | G20: 15–45 s / side | H20: 15 | I20: 45 | J20: RPE ≤7 | K20: Isometric: +5 s per session to 45 s, then longer lever | M20: =IF(UPPER(L20)="Y",F20+2,F20) -> 2 | N20: =IF(A20="Home",M20,IF('Start here'!$C$13="",M20,MAX(1,ROUND(M20*'Start here'!$C$13,0)))) -> 1 | O20: Short lever (knee on bench) first. Move to Saturday if adductors are tight for class.
A21: Wed | B21: All | C21: 5 | D21: Standing cable hip abduction | E21: Hip abduction, hip extended | F21: 2 | G21: 12–15 / side | H21: 12 | I21: 15 | J21: RIR 2 | K21: Double progression | M21: =IF(UPPER(L21)="Y",F21+2,F21) -> 2 | N21: =IF(A21="Home",M21,IF('Start here'!$C$13="",M21,MAX(1,ROUND(M21*'Start here'!$C$13,0)))) -> 1 | O21: Shares the cable with the Pallof press.
A22: Wed | B22: All | C22: 6 | D22: Hip hike off step (DB in working-side hand) | E22: Pelvic elevation / hip hike L & R | F22: 2 | G22: 10–15 / side | H22: 10 | I22: 15 | J22: RIR 2 | K22: Double progression | M22: =IF(UPPER(L22)="Y",F22+2,F22) -> 2 | N22: =IF(A22="Home",M22,IF('Start here'!$C$13="",M22,MAX(1,ROUND(M22*'Start here'!$C$13,0)))) -> 1
A23: Wed | B23: All | C23: 7 | D23: Seated cable rotation (hips fixed) or rotary torso machine | E23: Spinal rotation L & R | F23: 2 | G23: 10–12 / side | H23: 10 | I23: 12 | J23: RIR 2 | K23: Double progression | M23: =IF(UPPER(L23)="Y",F23+2,F23) -> 2 | N23: =IF(A23="Home",M23,IF('Start here'!$C$13="",M23,MAX(1,ROUND(M23*'Start here'!$C$13,0)))) -> 1 | O23: Replaces the woodchop, which is mostly hips.
A24: Wed | B24: All | C24: 8 | D24: Pallof press | E24: Anti-rotation | F24: 2 | G24: 10 / side | H24: 8 | I24: 12 | J24: RIR 2 | K24: Double progression | M24: =IF(UPPER(L24)="Y",F24+2,F24) -> 2 | N24: =IF(A24="Home",M24,IF('Start here'!$C$13="",M24,MAX(1,ROUND(M24*'Start here'!$C$13,0)))) -> 1
A25: Wed | B25: All | C25: 9 | D25: Suitcase carry | E25: One-hand carry; anti-lateral flexion | F25: 2 | G25: 20 m / side | H25: 15 | I25: 25 | J25: Hard but level hips | K25: Carry: hit top distance, then add load | M25: =IF(UPPER(L25)="Y",F25+2,F25) -> 2 | N25: =IF(A25="Home",M25,IF('Start here'!$C$13="",M25,MAX(1,ROUND(M25*'Start here'!$C$13,0)))) -> 1 | O25: Weaker side first; match it on the other side.
A26: Wed | B26: All | C26: 10 | D26: Neck harness: flexion, extension, lateral L, lateral R | E26: Neck flexion; extension; lateral flexion L & R | F26: 4 | G26: 15–20 (1 set per direction) | H26: 15 | I26: 20 | J26: RIR 3 | K26: Double progression; +1–2.5 kg steps | M26: =IF(UPPER(L26)="Y",F26+2,F26) -> 4 | N26: =IF(A26="Home",M26,IF('Start here'!$C$13="",M26,MAX(1,ROUND(M26*'Start here'!$C$13,0)))) -> 2 | O26: Isometrics only weeks 1–2. See Entry ramps.
A27: Thu | B27: All | C27: 1 | D27: Overhead press | E27: Vertical push; shoulder flexion; scapular upward rotation | F27: 4 | G27: Wave (see Plan) | J27: Wave RPE | K27: Main lift | M27: =IF(UPPER(L27)="Y",F27+2,F27) -> 4 | N27: =IF(A27="Home",M27,IF('Start here'!$C$13="",M27,MAX(1,ROUND(M27*'Start here'!$C$13,0)))) -> 2 | O27: Front raise dropped: the presses already load shoulder flexion.
A28: Thu | B28: All | C28: 2 | D28: Weighted pull-up | E28: Vertical pull; shoulder adduction; scapular depression & downward rotation | F28: 4 | G28: 4–6 | H28: 4 | I28: 6 | J28: RIR 1–2 | K28: Double progression (added kg) | M28: =IF(UPPER(L28)="Y",F28+2,F28) -> 4 | N28: =IF(A28="Home",M28,IF('Start here'!$C$13="",M28,MAX(1,ROUND(M28*'Start here'!$C$13,0)))) -> 2 | O28: Warm up with 2×8 scapular pull-ups (scapular depression).
A29: Thu | B29: All | C29: 3 | D29: Incline barbell bench | E29: Incline push; 2nd bench exposure | F29: 3 | G29: 4–6 | H29: 4 | I29: 6 | J29: RPE 7 | K29: Second-day lift (calculator) | M29: =IF(UPPER(L29)="Y",F29+2,F29) -> 3 | N29: =IF(A29="Home",M29,IF('Start here'!$C$13="",M29,MAX(1,ROUND(M29*'Start here'!$C$13,0)))) -> 2 | O29: Paused bench is a fine swap.
A30: Thu | B30: All | C30: 4 | D30: Straight-arm pulldown | E30: Shoulder extension | F30: 2 | G30: 10–15 | H30: 10 | I30: 15 | J30: RIR 1–2 | K30: Double progression | M30: =IF(UPPER(L30)="Y",F30+2,F30) -> 2 | N30: =IF(A30="Home",M30,IF('Start here'!$C$13="",M30,MAX(1,ROUND(M30*'Start here'!$C$13,0)))) -> 1
A31: Thu | B31: All | C31: 5 | D31: Lateral raise (cable or DB) | E31: Shoulder abduction; scapular upward rotation | F31: 3 | G31: 12–20 | H31: 12 | I31: 20 | J31: RIR 1–2 | K31: Double progression + ready-to-jump rule | M31: =IF(UPPER(L31)="Y",F31+2,F31) -> 3 | N31: =IF(A31="Home",M31,IF('Start here'!$C$13="",M31,MAX(1,ROUND(M31*'Start here'!$C$13,0)))) -> 2 | O31: Small-jump problem: on a cable, rest a 1.25 kg plate on the top of the stack, or use the Accessory log jump rule.
A32: Thu | B32: All | C32: 6 | D32: Shrug | E32: Scapular elevation | F32: 2 | G32: 8–12 | H32: 8 | I32: 12 | J32: RIR 1–2 | K32: Double progression | M32: =IF(UPPER(L32)="Y",F32+2,F32) -> 2 | N32: =IF(A32="Home",M32,IF('Start here'!$C$13="",M32,MAX(1,ROUND(M32*'Start here'!$C$13,0)))) -> 1 | O32: Straps.
A33: Thu | B33: All | C33: 7 | D33: Cable external rotation | E33: Shoulder external rotation | F33: 2 | G33: 12–20 | H33: 12 | I33: 20 | J33: RIR 2 | K33: Double progression | M33: =IF(UPPER(L33)="Y",F33+2,F33) -> 2 | N33: =IF(A33="Home",M33,IF('Start here'!$C$13="",M33,MAX(1,ROUND(M33*'Start here'!$C$13,0)))) -> 1 | O33: Superset with internal rotation.
A34: Thu | B34: All | C34: 8 | D34: Cable internal rotation | E34: Shoulder internal rotation | F34: 2 | G34: 12–20 | H34: 12 | I34: 20 | J34: RIR 2 | K34: Double progression | M34: =IF(UPPER(L34)="Y",F34+2,F34) -> 2 | N34: =IF(A34="Home",M34,IF('Start here'!$C$13="",M34,MAX(1,ROUND(M34*'Start here'!$C$13,0)))) -> 1
A35: Fri | B35: All | C35: 1 | D35: Deadlift | E35: Hinge; hip extension; support grip | F35: 4 | G35: Wave (see Plan) | J35: Wave RPE | K35: Main lift | M35: =IF(UPPER(L35)="Y",F35+2,F35) -> 4 | N35: =IF(A35="Home",M35,IF('Start here'!$C$13="",M35,MAX(1,ROUND(M35*'Start here'!$C$13,0)))) -> 2 | O35: Straps on back-off sets. Heaviest day sits on the no-class night.
A36: Fri | B36: All | C36: 2 | D36: Hip thrust (machine if available) | E36: Bridge / hip extension, knee bent | F36: 3 | G36: 6–10 | H36: 6 | I36: 10 | J36: RIR 1–2 | K36: Double progression | M36: =IF(UPPER(L36)="Y",F36+2,F36) -> 3 | N36: =IF(A36="Home",M36,IF('Start here'!$C$13="",M36,MAX(1,ROUND(M36*'Start here'!$C$13,0)))) -> 2
A37: Fri | B37: All | C37: 3 | D37: Lying leg curl | E37: Knee flexion, hip extended | F37: 3 | G37: 6–10 | H37: 6 | I37: 10 | J37: RIR 1–2 | K37: Double progression | M37: =IF(UPPER(L37)="Y",F37+2,F37) -> 3 | N37: =IF(A37="Home",M37,IF('Start here'!$C$13="",M37,MAX(1,ROUND(M37*'Start here'!$C$13,0)))) -> 2 | O37: Nordic curl is optional instead, only with a solid heel anchor and after its entry ramp.
A38: Fri | B38: All | C38: 4 | D38: Leg extension | E38: Knee extension, hip flexed | F38: 2 | G38: 10–15 | H38: 10 | I38: 15 | J38: RIR 1–2 | K38: Double progression | M38: =IF(UPPER(L38)="Y",F38+2,F38) -> 2 | N38: =IF(A38="Home",M38,IF('Start here'!$C$13="",M38,MAX(1,ROUND(M38*'Start here'!$C$13,0)))) -> 1 | O38: Moved off Monday so quads are fresher for class.
A39: Fri | B39: All | C39: 5 | D39: Reverse Nordic (heels under DB rack, on a mat) | E39: Knee extension, hip extended | F39: 2 | G39: 6–10 | H39: 6 | I39: 10 | J39: RIR 2–3 | K39: Range first, then hold a plate | M39: =IF(UPPER(L39)="Y",F39+2,F39) -> 2 | N39: =IF(A39="Home",M39,IF('Start here'!$C$13="",M39,MAX(1,ROUND(M39*'Start here'!$C$13,0)))) -> 1 | O39: See Entry ramps.
A40: Fri | B40: All | C40: 6 | D40: Standing calf raise | E40: Plantar flexion, knee straight (gastrocnemius) | F40: 3 | G40: 8–12 | H40: 8 | I40: 12 | J40: RIR 1–2 | K40: Double progression | M40: =IF(UPPER(L40)="Y",F40+2,F40) -> 3 | N40: =IF(A40="Home",M40,IF('Start here'!$C$13="",M40,MAX(1,ROUND(M40*'Start here'!$C$13,0)))) -> 2
...

Sheet Plan
A1: Week | B1: Week starts | C1: Phase | D1: Block week | E1: Volume % | F1: Accessory RPE cap | G1: Top-set reps | H1: Top-set RPE | I1: Back-off % below top | J1: Back-off sets | K1: Saturday | L1: Note
A2: 1 | B2: ='Start here'!$C$5+7*(A2-1) -> 46307 | C2: Ramp | D2: 1 | E2: 0.5 | F2: 6 | G2: 5 | H2: 6 | I2: 0.1 | J2: 3 × 5 | K2: =IF(ISODD(A2),"A","B") -> A | L2: Re-learn the lifts. New risky work: 1 set (see Entry ramps).
A3: 2 | B3: ='Start here'!$C$5+7*(A3-1) -> 46314 | C3: Ramp | D3: 2 | E3: 0.6 | F3: 6.5 | G3: 5 | H3: 6.5 | I3: 0.1 | J3: 3 × 5 | K3: =IF(ISODD(A3),"A","B") -> B | L3: New risky work: 2 sets.
A4: 3 | B4: ='Start here'!$C$5+7*(A4-1) -> 46321 | C4: Ramp | D4: 3 | E4: 0.7 | F4: 7 | G4: 5 | H4: 7 | I4: 0.1 | J4: 3 × 5 | K4: =IF(ISODD(A4),"A","B") -> A
A5: 4 | B5: ='Start here'!$C$5+7*(A5-1) -> 46328 | C5: Ramp | D5: 4 | E5: 0.8 | F5: 7 | G5: 5 | H5: 7 | I5: 0.1 | J5: 3 × 5 | K5: =IF(ISODD(A5),"A","B") -> B
A6: 5 | B6: ='Start here'!$C$5+7*(A6-1) -> 46335 | C6: Ramp | D6: 5 | E6: 0.9 | F6: 7.5 | G6: 5 | H6: 7.5 | I6: 0.1 | J6: 3 × 5 | K6: =IF(ISODD(A6),"A","B") -> A
A7: 6 | B7: ='Start here'!$C$5+7*(A7-1) -> 46342 | C7: Ramp | D7: 6 | E7: 1 | F7: 8 | G7: 5 | H7: 8 | I7: 0.1 | J7: 3 × 5 | K7: =IF(ISODD(A7),"A","B") -> B | L7: Last ramp week. Its e1RMs seed Block 1.
A8: 7 | B8: ='Start here'!$C$5+7*(A8-1) -> 46349 | C8: Ramp | D8: 7 | E8: 0.55 | F8: 6 | G8: 5 | H8: 6 | I8: 0.1 | J8: 1 × 5 at the same load | K8: =IF(ISODD(A8),"A","B") -> A | L8: Deload: about half the sets, loads ~90%, RPE ≤6.
A9: 8 | B9: ='Start here'!$C$5+7*(A9-1) -> 46356 | C9: Block 1 | D9: 1 | E9: 1 | F9: 8 | G9: 5 | H9: 8 | I9: 0.1 | J9: 3 × 5 | K9: =IF(ISODD(A9),"A","B") -> B | L9: Pick this block's 4–5 priority items in Program. Elbow variants: odd list.
A10: 9 | B10: ='Start here'!$C$5+7*(A10-1) -> 46363 | C10: Block 1 | D10: 2 | E10: 1 | F10: 8 | G10: 3 | H10: 8 | I10: 0.1 | J10: 3 × 3 | K10: =IF(ISODD(A10),"A","B") -> A
A11: 10 | B11: ='Start here'!$C$5+7*(A11-1) -> 46370 | C11: Block 1 | D11: 3 | E11: 1 | F11: 8 | G11: 2 | H11: 8.5 | I11: 0.12 | J11: 3 × 3 | K11: =IF(ISODD(A11),"A","B") -> B
A12: 11 | B12: ='Start here'!$C$5+7*(A12-1) -> 46377 | C12: Block 1 | D12: 4 | E12: 1 | F12: 8 | G12: 5 | H12: 8 | I12: 0.1 | J12: 3 × 5 | K12: =IF(ISODD(A12),"A","B") -> A
A13: 12 | B13: ='Start here'!$C$5+7*(A13-1) -> 46384 | C13: Block 1 | D13: 5 | E13: 1 | F13: 8 | G13: 3 | H13: 8 | I13: 0.1 | J13: 3 × 3 | K13: =IF(ISODD(A13),"A","B") -> B
A14: 13 | B14: ='Start here'!$C$5+7*(A14-1) -> 46391 | C14: Block 1 | D14: 6 | E14: 0.55 | F14: 6 | G14: 5 | H14: 6 | I14: 0.1 | J14: 1 × 5 at the same load | K14: =IF(ISODD(A14),"A","B") -> A | L14: Deload: about half the sets, loads ~90%, RPE ≤6.
A15: 14 | B15: ='Start here'!$C$5+7*(A15-1) -> 46398 | C15: Block 1 | D15: 7 | E15: 1 | F15: 8 | G15: 5 | H15: 8 | I15: 0.1 | J15: 3 × 5 | K15: =IF(ISODD(A15),"A","B") -> B
A16: 15 | B16: ='Start here'!$C$5+7*(A16-1) -> 46405 | C16: Block 1 | D16: 8 | E16: 1 | F16: 8 | G16: 3 | H16: 8 | I16: 0.1 | J16: 3 × 3 | K16: =IF(ISODD(A16),"A","B") -> A
A17: 16 | B17: ='Start here'!$C$5+7*(A17-1) -> 46412 | C17: Block 1 | D17: 9 | E17: 1 | F17: 8 | G17: 2 | H17: 8.5 | I17: 0.12 | J17: 3 × 3 | K17: =IF(ISODD(A17),"A","B") -> B
A18: 17 | B18: ='Start here'!$C$5+7*(A18-1) -> 46419 | C18: Block 1 | D18: 10 | E18: 1 | F18: 8 | G18: 5 | H18: 8 | I18: 0.1 | J18: 3 × 5 | K18: =IF(ISODD(A18),"A","B") -> A
A19: 18 | B19: ='Start here'!$C$5+7*(A19-1) -> 46426 | C19: Block 1 | D19: 11 | E19: 1 | F19: 8 | G19: 1 | H19: 9 | I19: 0.12 | J19: 2 × 3 | K19: =IF(ISODD(A19),"A","B") -> B | L19: Test: one top single @RPE 9. That e1RM is the new baseline. Also run the Tests sheet.
A20: 19 | B20: ='Start here'!$C$5+7*(A20-1) -> 46433 | C20: Block 1 | D20: 12 | E20: 0.55 | F20: 6 | G20: 5 | H20: 6 | I20: 0.1 | J20: 1 × 5 at the same load | K20: =IF(ISODD(A20),"A","B") -> A | L20: Deload: about half the sets, loads ~90%, RPE ≤6. Good week for exams or gradings.
A21: 20 | B21: ='Start here'!$C$5+7*(A21-1) -> 46440 | C21: Block 2 | D21: 1 | E21: 1 | F21: 8 | G21: 5 | H21: 8 | I21: 0.1 | J21: 3 × 5 | K21: =IF(ISODD(A21),"A","B") -> B | L21: Pick this block's 4–5 priority items in Program. Elbow variants: even list.
A22: 21 | B22: ='Start here'!$C$5+7*(A22-1) -> 46447 | C22: Block 2 | D22: 2 | E22: 1 | F22: 8 | G22: 3 | H22: 8 | I22: 0.1 | J22: 3 × 3 | K22: =IF(ISODD(A22),"A","B") -> A
A23: 22 | B23: ='Start here'!$C$5+7*(A23-1) -> 46454 | C23: Block 2 | D23: 3 | E23: 1 | F23: 8 | G23: 2 | H23: 8.5 | I23: 0.12 | J23: 3 × 3 | K23: =IF(ISODD(A23),"A","B") -> B
A24: 23 | B24: ='Start here'!$C$5+7*(A24-1) -> 46461 | C24: Block 2 | D24: 4 | E24: 1 | F24: 8 | G24: 5 | H24: 8 | I24: 0.1 | J24: 3 × 5 | K24: =IF(ISODD(A24),"A","B") -> A
A25: 24 | B25: ='Start here'!$C$5+7*(A25-1) -> 46468 | C25: Block 2 | D25: 5 | E25: 1 | F25: 8 | G25: 3 | H25: 8 | I25: 0.1 | J25: 3 × 3 | K25: =IF(ISODD(A25),"A","B") -> B
A26: 25 | B26: ='Start here'!$C$5+7*(A26-1) -> 46475 | C26: Block 2 | D26: 6 | E26: 0.55 | F26: 6 | G26: 5 | H26: 6 | I26: 0.1 | J26: 1 × 5 at the same load | K26: =IF(ISODD(A26),"A","B") -> A | L26: Deload: about half the sets, loads ~90%, RPE ≤6.
A27: 26 | B27: ='Start here'!$C$5+7*(A27-1) -> 46482 | C27: Block 2 | D27: 7 | E27: 1 | F27: 8 | G27: 5 | H27: 8 | I27: 0.1 | J27: 3 × 5 | K27: =IF(ISODD(A27),"A","B") -> B
A28: 27 | B28: ='Start here'!$C$5+7*(A28-1) -> 46489 | C28: Block 2 | D28: 8 | E28: 1 | F28: 8 | G28: 3 | H28: 8 | I28: 0.1 | J28: 3 × 3 | K28: =IF(ISODD(A28),"A","B") -> A
A29: 28 | B29: ='Start here'!$C$5+7*(A29-1) -> 46496 | C29: Block 2 | D29: 9 | E29: 1 | F29: 8 | G29: 2 | H29: 8.5 | I29: 0.12 | J29: 3 × 3 | K29: =IF(ISODD(A29),"A","B") -> B
A30: 29 | B30: ='Start here'!$C$5+7*(A30-1) -> 46503 | C30: Block 2 | D30: 10 | E30: 1 | F30: 8 | G30: 5 | H30: 8 | I30: 0.1 | J30: 3 × 5 | K30: =IF(ISODD(A30),"A","B") -> A
A31: 30 | B31: ='Start here'!$C$5+7*(A31-1) -> 46510 | C31: Block 2 | D31: 11 | E31: 1 | F31: 8 | G31: 1 | H31: 9 | I31: 0.12 | J31: 2 × 3 | K31: =IF(ISODD(A31),"A","B") -> B | L31: Test: one top single @RPE 9. That e1RM is the new baseline. Also run the Tests sheet.
A32: 31 | B32: ='Start here'!$C$5+7*(A32-1) -> 46517 | C32: Block 2 | D32: 12 | E32: 0.55 | F32: 6 | G32: 5 | H32: 6 | I32: 0.1 | J32: 1 × 5 at the same load | K32: =IF(ISODD(A32),"A","B") -> A | L32: Deload: about half the sets, loads ~90%, RPE ≤6. Good week for exams or gradings.
A34: Blue = editable plan values. To continue past week 31, copy the 12 Block 2 rows below and renumber Week. Block weeks 1–5: 5s / 3s / singles wave. 6 and 12: deload. 11: test single.

Sheet Main lifts
A1: NEXT SESSION
A2: Suggested loads from your best e1RM in the last 21 days (all-time best if none). Rounded to 2.5 kg.
A3: Lift | B3: Day | C3: Best e1RM (21 d) | D3: Best e1RM (all) | E3: Target reps | F3: Target RPE | G3: Top set kg | H3: Back-off kg | I3: Back-off sets
A4: Back squat | B4: Mon | C4: =_xlfn.MAXIFS($G$14:$G$313,$C$14:$C$313,A4,$A$14:$A$313,">="&(TODAY()-21)) -> 0 | D4: =_xlfn.MAXIFS($G$14:$G$313,$C$14:$C$313,A4) -> 0 | E4: =IFERROR(INDEX(Plan!$G$2:$G$32,MATCH('Start here'!$C$8,Plan!$A$2:$A$32,0)),5) -> 5 | F4: =IFERROR(INDEX(Plan!$H$2:$H$32,MATCH('Start here'!$C$8,Plan!$A$2:$A$32,0)),7) -> 6 | G4: =IF(IF(C4>0,C4,D4)=0,"Log a session first",IF(E4+10-F4<=1,MROUND(IF(C4>0,C4,D4),2.5),MROUND(IF(C4>0,C4,D4)/(1+(E4+10-F4)/30),2.5))) -> Log a session first | H4: =IF(ISNUMBER(G4),MROUND(G4*(1-IFERROR(INDEX(Plan!$I$2:$I$32,MATCH('Start here'!$C$8,Plan!$A$2:$A$32,0)),0.1)),2.5),"") | I4: =IFERROR(INDEX(Plan!$J$2:$J$32,MATCH('Start here'!$C$8,Plan!$A$2:$A$32,0)),"") -> 3 × 5
A5: Bench press | B5: Tue | C5: =_xlfn.MAXIFS($G$14:$G$313,$C$14:$C$313,A5,$A$14:$A$313,">="&(TODAY()-21)) -> 0 | D5: =_xlfn.MAXIFS($G$14:$G$313,$C$14:$C$313,A5) -> 0 | E5: =IFERROR(INDEX(Plan!$G$2:$G$32,MATCH('Start here'!$C$8,Plan!$A$2:$A$32,0)),5) -> 5 | F5: =IFERROR(INDEX(Plan!$H$2:$H$32,MATCH('Start here'!$C$8,Plan!$A$2:$A$32,0)),7) -> 6 | G5: =IF(IF(C5>0,C5,D5)=0,"Log a session first",IF(E5+10-F5<=1,MROUND(IF(C5>0,C5,D5),2.5),MROUND(IF(C5>0,C5,D5)/(1+(E5+10-F5)/30),2.5))) -> Log a session first | H5: =IF(ISNUMBER(G5),MROUND(G5*(1-IFERROR(INDEX(Plan!$I$2:$I$32,MATCH('Start here'!$C$8,Plan!$A$2:$A$32,0)),0.1)),2.5),"") | I5: =IFERROR(INDEX(Plan!$J$2:$J$32,MATCH('Start here'!$C$8,Plan!$A$2:$A$32,0)),"") -> 3 × 5
A6: Overhead press | B6: Thu | C6: =_xlfn.MAXIFS($G$14:$G$313,$C$14:$C$313,A6,$A$14:$A$313,">="&(TODAY()-21)) -> 0 | D6: =_xlfn.MAXIFS($G$14:$G$313,$C$14:$C$313,A6) -> 0 | E6: =IFERROR(INDEX(Plan!$G$2:$G$32,MATCH('Start here'!$C$8,Plan!$A$2:$A$32,0)),5) -> 5 | F6: =IFERROR(INDEX(Plan!$H$2:$H$32,MATCH('Start here'!$C$8,Plan!$A$2:$A$32,0)),7) -> 6 | G6: =IF(IF(C6>0,C6,D6)=0,"Log a session first",IF(E6+10-F6<=1,MROUND(IF(C6>0,C6,D6),2.5),MROUND(IF(C6>0,C6,D6)/(1+(E6+10-F6)/30),2.5))) -> Log a session first | H6: =IF(ISNUMBER(G6),MROUND(G6*(1-IFERROR(INDEX(Plan!$I$2:$I$32,MATCH('Start here'!$C$8,Plan!$A$2:$A$32,0)),0.1)),2.5),"") | I6: =IFERROR(INDEX(Plan!$J$2:$J$32,MATCH('Start here'!$C$8,Plan!$A$2:$A$32,0)),"") -> 3 × 5
A7: Deadlift | B7: Fri | C7: =_xlfn.MAXIFS($G$14:$G$313,$C$14:$C$313,A7,$A$14:$A$313,">="&(TODAY()-21)) -> 0 | D7: =_xlfn.MAXIFS($G$14:$G$313,$C$14:$C$313,A7) -> 0 | E7: =IFERROR(INDEX(Plan!$G$2:$G$32,MATCH('Start here'!$C$8,Plan!$A$2:$A$32,0)),5) -> 5 | F7: =IFERROR(INDEX(Plan!$H$2:$H$32,MATCH('Start here'!$C$8,Plan!$A$2:$A$32,0)),7) -> 6 | G7: =IF(IF(C7>0,C7,D7)=0,"Log a session first",IF(E7+10-F7<=1,MROUND(IF(C7>0,C7,D7),2.5),MROUND(IF(C7>0,C7,D7)/(1+(E7+10-F7)/30),2.5))) -> Log a session first | H7: =IF(ISNUMBER(G7),MROUND(G7*(1-IFERROR(INDEX(Plan!$I$2:$I$32,MATCH('Start here'!$C$8,Plan!$A$2:$A$32,0)),0.1)),2.5),"") | I7: =IFERROR(INDEX(Plan!$J$2:$J$32,MATCH('Start here'!$C$8,Plan!$A$2:$A$32,0)),"") -> 3 × 5
A8: Incline barbell bench | B8: Thu | C8: =_xlfn.MAXIFS($G$14:$G$313,$C$14:$C$313,A8,$A$14:$A$313,">="&(TODAY()-21)) -> 0 | D8: =_xlfn.MAXIFS($G$14:$G$313,$C$14:$C$313,A8) -> 0 | E8: 4 | F8: 7 | G8: =IF(IF(C8>0,C8,D8)=0,"Log a session first",IF(E8+10-F8<=1,MROUND(IF(C8>0,C8,D8),2.5),MROUND(IF(C8>0,C8,D8)/(1+(E8+10-F8)/30),2.5))) -> Log a session first | H8: =IF(ISNUMBER(G8),G8,"") | I8: 3 sets at the top-set load
A9: Front squat | B9: Sat | C9: =_xlfn.MAXIFS($G$14:$G$313,$C$14:$C$313,A9,$A$14:$A$313,">="&(TODAY()-21)) -> 0 | D9: =_xlfn.MAXIFS($G$14:$G$313,$C$14:$C$313,A9) -> 0 | E9: 4 | F9: 7 | G9: =IF(IF(C9>0,C9,D9)=0,"Log a session first",IF(E9+10-F9<=1,MROUND(IF(C9>0,C9,D9),2.5),MROUND(IF(C9>0,C9,D9)/(1+(E9+10-F9)/30),2.5))) -> Log a session first | H9: =IF(ISNUMBER(G9),G9,"") | I9: 3 sets at the top-set load
A10: Weighted pull-up and all other lifts use the Accessory log. Incline and front squat are second-day lifts: fixed 3 sets of ~4 @RPE 7 (blue cells editable). Deload weeks: one top set of 5 @RPE 6 plus 1 × 5 at the same load.
A12: LOG – one row per top set
A13: Date | B13: Week | C13: Lift | D13: Top set kg | E13: Reps | F13: RPE | G13: e1RM | H13: Back-off kg | I13: Back-off reps (each) | J13: Prior best e1RM | K13: Trend
A14: 46307 | B14: =IF(A14="","",INT((A14-'Start here'!$C$5)/7)+1) -> 1 | C14: Example: Back squat | D14: 100 | E14: 5 | F14: 6.5 | G14: =IF(OR(D14="",E14=""),"",IF(E14+10-IF(F14="",10,F14)<=1,D14,ROUND(D14*(1+(E14+10-IF(F14="",10,F14))/30),1))) -> 128.3 | H14: 90 | I14: 5 | J14: =IF(OR(C14="",G14=""),"",IF(_xlfn.MAXIFS($G$13:G13,$C$13:C13,C14)=0,"",_xlfn.MAXIFS($G$13:G13,$C$13:C13,C14))) | K14: =IF(OR(G14="",J14=""),"",IF(G14<0.95*J14,"Below trend","OK"))
B15: =IF(A15="","",INT((A15-'Start here'!$C$5)/7)+1) | G15: =IF(OR(D15="",E15=""),"",IF(E15+10-IF(F15="",10,F15)<=1,D15,ROUND(D15*(1+(E15+10-IF(F15="",10,F15))/30),1))) | J15: =IF(OR(C15="",G15=""),"",IF(_xlfn.MAXIFS($G$13:G14,$C$13:C14,C15)=0,"",_xlfn.MAXIFS($G$13:G14,$C$13:C14,C15))) | K15: =IF(OR(G15="",J15=""),"",IF(G15<0.95*J15,"Below trend","OK"))
B16: =IF(A16="","",INT((A16-'Start here'!$C$5)/7)+1) | G16: =IF(OR(D16="",E16=""),"",IF(E16+10-IF(F16="",10,F16)<=1,D16,ROUND(D16*(1+(E16+10-IF(F16="",10,F16))/30),1))) | J16: =IF(OR(C16="",G16=""),"",IF(_xlfn.MAXIFS($G$13:G15,$C$13:C15,C16)=0,"",_xlfn.MAXIFS($G$13:G15,$C$13:C15,C16))) | K16: =IF(OR(G16="",J16=""),"",IF(G16<0.95*J16,"Below trend","OK"))
B17: =IF(A17="","",INT((A17-'Start here'!$C$5)/7)+1) | G17: =IF(OR(D17="",E17=""),"",IF(E17+10-IF(F17="",10,F17)<=1,D17,ROUND(D17*(1+(E17+10-IF(F17="",10,F17))/30),1))) | J17: =IF(OR(C17="",G17=""),"",IF(_xlfn.MAXIFS($G$13:G16,$C$13:C16,C17)=0,"",_xlfn.MAXIFS($G$13:G16,$C$13:C16,C17))) | K17: =IF(OR(G17="",J17=""),"",IF(G17<0.95*J17,"Below trend","OK"))
B18: =IF(A18="","",INT((A18-'Start here'!$C$5)/7)+1) | G18: =IF(OR(D18="",E18=""),"",IF(E18+10-IF(F18="",10,F18)<=1,D18,ROUND(D18*(1+(E18+10-IF(F18="",10,F18))/30),1))) | J18: =IF(OR(C18="",G18=""),"",IF(_xlfn.MAXIFS($G$13:G17,$C$13:C17,C18)=0,"",_xlfn.MAXIFS($G$13:G17,$C$13:C17,C18))) | K18: =IF(OR(G18="",J18=""),"",IF(G18<0.95*J18,"Below trend","OK"))
B19: =IF(A19="","",INT((A19-'Start here'!$C$5)/7)+1) | G19: =IF(OR(D19="",E19=""),"",IF(E19+10-IF(F19="",10,F19)<=1,D19,ROUND(D19*(1+(E19+10-IF(F19="",10,F19))/30),1))) | J19: =IF(OR(C19="",G19=""),"",IF(_xlfn.MAXIFS($G$13:G18,$C$13:C18,C19)=0,"",_xlfn.MAXIFS($G$13:G18,$C$13:C18,C19))) | K19: =IF(OR(G19="",J19=""),"",IF(G19<0.95*J19,"Below trend","OK"))
B20: =IF(A20="","",INT((A20-'Start here'!$C$5)/7)+1) | G20: =IF(OR(D20="",E20=""),"",IF(E20+10-IF(F20="",10,F20)<=1,D20,ROUND(D20*(1+(E20+10-IF(F20="",10,F20))/30),1))) | J20: =IF(OR(C20="",G20=""),"",IF(_xlfn.MAXIFS($G$13:G19,$C$13:C19,C20)=0,"",_xlfn.MAXIFS($G$13:G19,$C$13:C19,C20))) | K20: =IF(OR(G20="",J20=""),"",IF(G20<0.95*J20,"Below trend","OK"))
B21: =IF(A21="","",INT((A21-'Start here'!$C$5)/7)+1) | G21: =IF(OR(D21="",E21=""),"",IF(E21+10-IF(F21="",10,F21)<=1,D21,ROUND(D21*(1+(E21+10-IF(F21="",10,F21))/30),1))) | J21: =IF(OR(C21="",G21=""),"",IF(_xlfn.MAXIFS($G$13:G20,$C$13:C20,C21)=0,"",_xlfn.MAXIFS($G$13:G20,$C$13:C20,C21))) | K21: =IF(OR(G21="",J21=""),"",IF(G21<0.95*J21,"Below trend","OK"))
B22: =IF(A22="","",INT((A22-'Start here'!$C$5)/7)+1) | G22: =IF(OR(D22="",E22=""),"",IF(E22+10-IF(F22="",10,F22)<=1,D22,ROUND(D22*(1+(E22+10-IF(F22="",10,F22))/30),1))) | J22: =IF(OR(C22="",G22=""),"",IF(_xlfn.MAXIFS($G$13:G21,$C$13:C21,C22)=0,"",_xlfn.MAXIFS($G$13:G21,$C$13:C21,C22))) | K22: =IF(OR(G22="",J22=""),"",IF(G22<0.95*J22,"Below trend","OK"))
B23: =IF(A23="","",INT((A23-'Start here'!$C$5)/7)+1) | G23: =IF(OR(D23="",E23=""),"",IF(E23+10-IF(F23="",10,F23)<=1,D23,ROUND(D23*(1+(E23+10-IF(F23="",10,F23))/30),1))) | J23: =IF(OR(C23="",G23=""),"",IF(_xlfn.MAXIFS($G$13:G22,$C$13:C22,C23)=0,"",_xlfn.MAXIFS($G$13:G22,$C$13:C22,C23))) | K23: =IF(OR(G23="",J23=""),"",IF(G23<0.95*J23,"Below trend","OK"))
B24: =IF(A24="","",INT((A24-'Start here'!$C$5)/7)+1) | G24: =IF(OR(D24="",E24=""),"",IF(E24+10-IF(F24="",10,F24)<=1,D24,ROUND(D24*(1+(E24+10-IF(F24="",10,F24))/30),1))) | J24: =IF(OR(C24="",G24=""),"",IF(_xlfn.MAXIFS($G$13:G23,$C$13:C23,C24)=0,"",_xlfn.MAXIFS($G$13:G23,$C$13:C23,C24))) | K24: =IF(OR(G24="",J24=""),"",IF(G24<0.95*J24,"Below trend","OK"))
B25: =IF(A25="","",INT((A25-'Start here'!$C$5)/7)+1) | G25: =IF(OR(D25="",E25=""),"",IF(E25+10-IF(F25="",10,F25)<=1,D25,ROUND(D25*(1+(E25+10-IF(F25="",10,F25))/30),1))) | J25: =IF(OR(C25="",G25=""),"",IF(_xlfn.MAXIFS($G$13:G24,$C$13:C24,C25)=0,"",_xlfn.MAXIFS($G$13:G24,$C$13:C24,C25))) | K25: =IF(OR(G25="",J25=""),"",IF(G25<0.95*J25,"Below trend","OK"))
B26: =IF(A26="","",INT((A26-'Start here'!$C$5)/7)+1) | G26: =IF(OR(D26="",E26=""),"",IF(E26+10-IF(F26="",10,F26)<=1,D26,ROUND(D26*(1+(E26+10-IF(F26="",10,F26))/30),1))) | J26: =IF(OR(C26="",G26=""),"",IF(_xlfn.MAXIFS($G$13:G25,$C$13:C25,C26)=0,"",_xlfn.MAXIFS($G$13:G25,$C$13:C25,C26))) | K26: =IF(OR(G26="",J26=""),"",IF(G26<0.95*J26,"Below trend","OK"))
... B313: =IF(A313="","",INT((A313-'Start here'!$C$5)/7)+1) | G313: =IF(OR(D313="",E313=""),"",IF(E313+10-IF(F313="",10,F313)<=1,D313,ROUND(D313*(1+(E313+10-IF(F313="",10,F313))/30),1))) | J313: =IF(OR(C313="",G313=""),"",IF(_xlfn.MAXIFS($G$13:G312,$C$13:C312,C313)=0,"",_xlfn.MAXIFS($G$13:G312,$C$13:C312,C313))) | K313: =IF(OR(G313="",J313=""),"",IF(G313<0.95*J313,"Below trend","OK"))
A315: Grey row = example; overwrite it. 'Example:' names are ignored by the calculator. 'Below trend' twice in a row for a lift = deload next week.

Sheet Accessory log
A1: Date | B1: Exercise | C1: Load kg | D1: Set 1 | E1: Set 2 | F1: Set 3 | G1: Set 4 | H1: Range low | I1: Range high | J1: Sets done | K1: Action | L1: Next available kg | M1: Reps needed before that jump
A2: 46310 | B2: Lateral raise (cable or DB) | C2: 7.5 | D2: 20 | E2: 19 | F2: 18 | H2: =IF(B2="","",IFERROR(INDEX(Program!$H$2:$H$75,MATCH(B2,Program!$D$2:$D$75,0)),"")) -> 12 | I2: =IF(B2="","",IFERROR(INDEX(Program!$I$2:$I$75,MATCH(B2,Program!$D$2:$D$75,0)),"")) -> 20 | J2: =IF(COUNT(D2:G2)=0,"",COUNT(D2:G2)) -> 3 | K2: =IF(OR(J2="",I2=""),"",IF(MIN(D2:G2)>=I2,"Add load (smallest step)",IF(MAX(D2:G2)<H2,"Below range: if again, drop 5–10%","Same load, add reps"))) -> Same load, add reps | L2: 10 | M2: =IF(OR(L2="",C2="",H2="",C2=0),"",MAX(H2,ROUNDUP(30*((L2/C2)*(1+H2/30)-1),0))) -> 26
H3: =IF(B3="","",IFERROR(INDEX(Program!$H$2:$H$75,MATCH(B3,Program!$D$2:$D$75,0)),"")) | I3: =IF(B3="","",IFERROR(INDEX(Program!$I$2:$I$75,MATCH(B3,Program!$D$2:$D$75,0)),"")) | J3: =IF(COUNT(D3:G3)=0,"",COUNT(D3:G3)) | K3: =IF(OR(J3="",I3=""),"",IF(MIN(D3:G3)>=I3,"Add load (smallest step)",IF(MAX(D3:G3)<H3,"Below range: if again, drop 5–10%","Same load, add reps"))) | M3: =IF(OR(L3="",C3="",H3="",C3=0),"",MAX(H3,ROUNDUP(30*((L3/C3)*(1+H3/30)-1),0)))
H4: =IF(B4="","",IFERROR(INDEX(Program!$H$2:$H$75,MATCH(B4,Program!$D$2:$D$75,0)),"")) | I4: =IF(B4="","",IFERROR(INDEX(Program!$I$2:$I$75,MATCH(B4,Program!$D$2:$D$75,0)),"")) | J4: =IF(COUNT(D4:G4)=0,"",COUNT(D4:G4)) | K4: =IF(OR(J4="",I4=""),"",IF(MIN(D4:G4)>=I4,"Add load (smallest step)",IF(MAX(D4:G4)<H4,"Below range: if again, drop 5–10%","Same load, add reps"))) | M4: =IF(OR(L4="",C4="",H4="",C4=0),"",MAX(H4,ROUNDUP(30*((L4/C4)*(1+H4/30)-1),0)))
H5: =IF(B5="","",IFERROR(INDEX(Program!$H$2:$H$75,MATCH(B5,Program!$D$2:$D$75,0)),"")) | I5: =IF(B5="","",IFERROR(INDEX(Program!$I$2:$I$75,MATCH(B5,Program!$D$2:$D$75,0)),"")) | J5: =IF(COUNT(D5:G5)=0,"",COUNT(D5:G5)) | K5: =IF(OR(J5="",I5=""),"",IF(MIN(D5:G5)>=I5,"Add load (smallest step)",IF(MAX(D5:G5)<H5,"Below range: if again, drop 5–10%","Same load, add reps"))) | M5: =IF(OR(L5="",C5="",H5="",C5=0),"",MAX(H5,ROUNDUP(30*((L5/C5)*(1+H5/30)-1),0)))
H6: =IF(B6="","",IFERROR(INDEX(Program!$H$2:$H$75,MATCH(B6,Program!$D$2:$D$75,0)),"")) | I6: =IF(B6="","",IFERROR(INDEX(Program!$I$2:$I$75,MATCH(B6,Program!$D$2:$D$75,0)),"")) | J6: =IF(COUNT(D6:G6)=0,"",COUNT(D6:G6)) | K6: =IF(OR(J6="",I6=""),"",IF(MIN(D6:G6)>=I6,"Add load (smallest step)",IF(MAX(D6:G6)<H6,"Below range: if again, drop 5–10%","Same load, add reps"))) | M6: =IF(OR(L6="",C6="",H6="",C6=0),"",MAX(H6,ROUNDUP(30*((L6/C6)*(1+H6/30)-1),0)))
H7: =IF(B7="","",IFERROR(INDEX(Program!$H$2:$H$75,MATCH(B7,Program!$D$2:$D$75,0)),"")) | I7: =IF(B7="","",IFERROR(INDEX(Program!$I$2:$I$75,MATCH(B7,Program!$D$2:$D$75,0)),"")) | J7: =IF(COUNT(D7:G7)=0,"",COUNT(D7:G7)) | K7: =IF(OR(J7="",I7=""),"",IF(MIN(D7:G7)>=I7,"Add load (smallest step)",IF(MAX(D7:G7)<H7,"Below range: if again, drop 5–10%","Same load, add reps"))) | M7: =IF(OR(L7="",C7="",H7="",C7=0),"",MAX(H7,ROUNDUP(30*((L7/C7)*(1+H7/30)-1),0)))
H8: =IF(B8="","",IFERROR(INDEX(Program!$H$2:$H$75,MATCH(B8,Program!$D$2:$D$75,0)),"")) | I8: =IF(B8="","",IFERROR(INDEX(Program!$I$2:$I$75,MATCH(B8,Program!$D$2:$D$75,0)),"")) | J8: =IF(COUNT(D8:G8)=0,"",COUNT(D8:G8)) | K8: =IF(OR(J8="",I8=""),"",IF(MIN(D8:G8)>=I8,"Add load (smallest step)",IF(MAX(D8:G8)<H8,"Below range: if again, drop 5–10%","Same load, add reps"))) | M8: =IF(OR(L8="",C8="",H8="",C8=0),"",MAX(H8,ROUNDUP(30*((L8/C8)*(1+H8/30)-1),0)))
H9: =IF(B9="","",IFERROR(INDEX(Program!$H$2:$H$75,MATCH(B9,Program!$D$2:$D$75,0)),"")) | I9: =IF(B9="","",IFERROR(INDEX(Program!$I$2:$I$75,MATCH(B9,Program!$D$2:$D$75,0)),"")) | J9: =IF(COUNT(D9:G9)=0,"",COUNT(D9:G9)) | K9: =IF(OR(J9="",I9=""),"",IF(MIN(D9:G9)>=I9,"Add load (smallest step)",IF(MAX(D9:G9)<H9,"Below range: if again, drop 5–10%","Same load, add reps"))) | M9: =IF(OR(L9="",C9="",H9="",C9=0),"",MAX(H9,ROUNDUP(30*((L9/C9)*(1+H9/30)-1),0)))
H10: =IF(B10="","",IFERROR(INDEX(Program!$H$2:$H$75,MATCH(B10,Program!$D$2:$D$75,0)),"")) | I10: =IF(B10="","",IFERROR(INDEX(Program!$I$2:$I$75,MATCH(B10,Program!$D$2:$D$75,0)),"")) | J10: =IF(COUNT(D10:G10)=0,"",COUNT(D10:G10)) | K10: =IF(OR(J10="",I10=""),"",IF(MIN(D10:G10)>=I10,"Add load (smallest step)",IF(MAX(D10:G10)<H10,"Below range: if again, drop 5–10%","Same load, add reps"))) | M10: =IF(OR(L10="",C10="",H10="",C10=0),"",MAX(H10,ROUNDUP(30*((L10/C10)*(1+H10/30)-1),0)))
H11: =IF(B11="","",IFERROR(INDEX(Program!$H$2:$H$75,MATCH(B11,Program!$D$2:$D$75,0)),"")) | I11: =IF(B11="","",IFERROR(INDEX(Program!$I$2:$I$75,MATCH(B11,Program!$D$2:$D$75,0)),"")) | J11: =IF(COUNT(D11:G11)=0,"",COUNT(D11:G11)) | K11: =IF(OR(J11="",I11=""),"",IF(MIN(D11:G11)>=I11,"Add load (smallest step)",IF(MAX(D11:G11)<H11,"Below range: if again, drop 5–10%","Same load, add reps"))) | M11: =IF(OR(L11="",C11="",H11="",C11=0),"",MAX(H11,ROUNDUP(30*((L11/C11)*(1+H11/30)-1),0)))
H12: =IF(B12="","",IFERROR(INDEX(Program!$H$2:$H$75,MATCH(B12,Program!$D$2:$D$75,0)),"")) | I12: =IF(B12="","",IFERROR(INDEX(Program!$I$2:$I$75,MATCH(B12,Program!$D$2:$D$75,0)),"")) | J12: =IF(COUNT(D12:G12)=0,"",COUNT(D12:G12)) | K12: =IF(OR(J12="",I12=""),"",IF(MIN(D12:G12)>=I12,"Add load (smallest step)",IF(MAX(D12:G12)<H12,"Below range: if again, drop 5–10%","Same load, add reps"))) | M12: =IF(OR(L12="",C12="",H12="",C12=0),"",MAX(H12,ROUNDUP(30*((L12/C12)*(1+H12/30)-1),0)))
H13: =IF(B13="","",IFERROR(INDEX(Program!$H$2:$H$75,MATCH(B13,Program!$D$2:$D$75,0)),"")) | I13: =IF(B13="","",IFERROR(INDEX(Program!$I$2:$I$75,MATCH(B13,Program!$D$2:$D$75,0)),"")) | J13: =IF(COUNT(D13:G13)=0,"",COUNT(D13:G13)) | K13: =IF(OR(J13="",I13=""),"",IF(MIN(D13:G13)>=I13,"Add load (smallest step)",IF(MAX(D13:G13)<H13,"Below range: if again, drop 5–10%","Same load, add reps"))) | M13: =IF(OR(L13="",C13="",H13="",C13=0),"",MAX(H13,ROUNDUP(30*((L13/C13)*(1+H13/30)-1),0)))
H14: =IF(B14="","",IFERROR(INDEX(Program!$H$2:$H$75,MATCH(B14,Program!$D$2:$D$75,0)),"")) | I14: =IF(B14="","",IFERROR(INDEX(Program!$I$2:$I$75,MATCH(B14,Program!$D$2:$D$75,0)),"")) | J14: =IF(COUNT(D14:G14)=0,"",COUNT(D14:G14)) | K14: =IF(OR(J14="",I14=""),"",IF(MIN(D14:G14)>=I14,"Add load (smallest step)",IF(MAX(D14:G14)<H14,"Below range: if again, drop 5–10%","Same load, add reps"))) | M14: =IF(OR(L14="",C14="",H14="",C14=0),"",MAX(H14,ROUNDUP(30*((L14/C14)*(1+H14/30)-1),0)))
... H801: =IF(B801="","",IFERROR(INDEX(Program!$H$2:$H$75,MATCH(B801,Program!$D$2:$D$75,0)),"")) | I801: =IF(B801="","",IFERROR(INDEX(Program!$I$2:$I$75,MATCH(B801,Program!$D$2:$D$75,0)),"")) | J801: =IF(COUNT(D801:G801)=0,"",COUNT(D801:G801)) | K801: =IF(OR(J801="",I801=""),"",IF(MIN(D801:G801)>=I801,"Add load (smallest step)",IF(MAX(D801:G801)<H801,"Below range: if again, drop 5–10%","Same load, add reps"))) | M801: =IF(OR(L801="",C801="",H801="",C801=0),"",MAX(H801,ROUNDUP(30*((L801/C801)*(1+H801/30)-1),0)))
A803: Grey row = example; overwrite it. Sets = reps, seconds or metres, matching the Program range. 'Next available kg' is optional: type the next weight you can actually use and the last column shows how many reps you need at the current load before jumping (ready-to-jump rule). If that's above the range, keep adding reps or use fractional plates.

Sheet Readiness
A1: Date | B1: Week | C1: Sleep (1–5) | D1: Legs fresh (1–5) | E1: Energy (1–5) | F1: Total | G1: Today's call | H1: Kung fu felt flat? (Y/N) | I1: Worst joint pain (0–10) | J1: Which joint | K1: Pain action | L1: Session minutes | N1: Week | O1: Flat kung fu nights | P1: Sessions > 75 min | Q1: Flag
A2: 46307 | B2: =IF(A2="","",INT((A2-'Start here'!$C$5)/7)+1) -> 1 | C2: 4 | D2: 3 | E2: 4 | F2: =IF(COUNT(C2:E2)<3,"",SUM(C2:E2)) -> 11 | G2: =IF(F2="","",IF(F2<=6,"Technique and mobility only",IF(F2<=8,"Main lift top set only; −1 set on every accessory; RPE cap 7","Train as planned"))) -> Train as planned | H2: N | I2: 2 | J2: Left elbow | K2: =IF(I2="","",IF(I2>=5,"Drop that pattern this week",IF(I2>=3,"Swap that exercise","OK"))) -> OK | L2: 68 | N2: 1 | O2: =COUNTIFS($B$2:$B$301,N2,$H$2:$H$301,"Y") -> 0 | P2: =COUNTIFS($B$2:$B$301,N2,$L$2:$L$301,">75") -> 0 | Q2: =TRIM(IF(O2>=2,"Cut lower-body accessories 25% next week. ","")&IF(P2>=2,"Sessions running long: trim the cut-first list.",""))
B3: =IF(A3="","",INT((A3-'Start here'!$C$5)/7)+1) | F3: =IF(COUNT(C3:E3)<3,"",SUM(C3:E3)) | G3: =IF(F3="","",IF(F3<=6,"Technique and mobility only",IF(F3<=8,"Main lift top set only; −1 set on every accessory; RPE cap 7","Train as planned"))) | K3: =IF(I3="","",IF(I3>=5,"Drop that pattern this week",IF(I3>=3,"Swap that exercise","OK"))) | N3: 2 | O3: =COUNTIFS($B$2:$B$301,N3,$H$2:$H$301,"Y") -> 0 | P3: =COUNTIFS($B$2:$B$301,N3,$L$2:$L$301,">75") -> 0 | Q3: =TRIM(IF(O3>=2,"Cut lower-body accessories 25% next week. ","")&IF(P3>=2,"Sessions running long: trim the cut-first list.",""))
B4: =IF(A4="","",INT((A4-'Start here'!$C$5)/7)+1) | F4: =IF(COUNT(C4:E4)<3,"",SUM(C4:E4)) | G4: =IF(F4="","",IF(F4<=6,"Technique and mobility only",IF(F4<=8,"Main lift top set only; −1 set on every accessory; RPE cap 7","Train as planned"))) | K4: =IF(I4="","",IF(I4>=5,"Drop that pattern this week",IF(I4>=3,"Swap that exercise","OK"))) | N4: 3 | O4: =COUNTIFS($B$2:$B$301,N4,$H$2:$H$301,"Y") -> 0 | P4: =COUNTIFS($B$2:$B$301,N4,$L$2:$L$301,">75") -> 0 | Q4: =TRIM(IF(O4>=2,"Cut lower-body accessories 25% next week. ","")&IF(P4>=2,"Sessions running long: trim the cut-first list.",""))
B5: =IF(A5="","",INT((A5-'Start here'!$C$5)/7)+1) | F5: =IF(COUNT(C5:E5)<3,"",SUM(C5:E5)) | G5: =IF(F5="","",IF(F5<=6,"Technique and mobility only",IF(F5<=8,"Main lift top set only; −1 set on every accessory; RPE cap 7","Train as planned"))) | K5: =IF(I5="","",IF(I5>=5,"Drop that pattern this week",IF(I5>=3,"Swap that exercise","OK"))) | N5: 4 | O5: =COUNTIFS($B$2:$B$301,N5,$H$2:$H$301,"Y") -> 0 | P5: =COUNTIFS($B$2:$B$301,N5,$L$2:$L$301,">75") -> 0 | Q5: =TRIM(IF(O5>=2,"Cut lower-body accessories 25% next week. ","")&IF(P5>=2,"Sessions running long: trim the cut-first list.",""))
B6: =IF(A6="","",INT((A6-'Start here'!$C$5)/7)+1) | F6: =IF(COUNT(C6:E6)<3,"",SUM(C6:E6)) | G6: =IF(F6="","",IF(F6<=6,"Technique and mobility only",IF(F6<=8,"Main lift top set only; −1 set on every accessory; RPE cap 7","Train as planned"))) | K6: =IF(I6="","",IF(I6>=5,"Drop that pattern this week",IF(I6>=3,"Swap that exercise","OK"))) | N6: 5 | O6: =COUNTIFS($B$2:$B$301,N6,$H$2:$H$301,"Y") -> 0 | P6: =COUNTIFS($B$2:$B$301,N6,$L$2:$L$301,">75") -> 0 | Q6: =TRIM(IF(O6>=2,"Cut lower-body accessories 25% next week. ","")&IF(P6>=2,"Sessions running long: trim the cut-first list.",""))
B7: =IF(A7="","",INT((A7-'Start here'!$C$5)/7)+1) | F7: =IF(COUNT(C7:E7)<3,"",SUM(C7:E7)) | G7: =IF(F7="","",IF(F7<=6,"Technique and mobility only",IF(F7<=8,"Main lift top set only; −1 set on every accessory; RPE cap 7","Train as planned"))) | K7: =IF(I7="","",IF(I7>=5,"Drop that pattern this week",IF(I7>=3,"Swap that exercise","OK"))) | N7: 6 | O7: =COUNTIFS($B$2:$B$301,N7,$H$2:$H$301,"Y") -> 0 | P7: =COUNTIFS($B$2:$B$301,N7,$L$2:$L$301,">75") -> 0 | Q7: =TRIM(IF(O7>=2,"Cut lower-body accessories 25% next week. ","")&IF(P7>=2,"Sessions running long: trim the cut-first list.",""))
B8: =IF(A8="","",INT((A8-'Start here'!$C$5)/7)+1) | F8: =IF(COUNT(C8:E8)<3,"",SUM(C8:E8)) | G8: =IF(F8="","",IF(F8<=6,"Technique and mobility only",IF(F8<=8,"Main lift top set only; −1 set on every accessory; RPE cap 7","Train as planned"))) | K8: =IF(I8="","",IF(I8>=5,"Drop that pattern this week",IF(I8>=3,"Swap that exercise","OK"))) | N8: 7 | O8: =COUNTIFS($B$2:$B$301,N8,$H$2:$H$301,"Y") -> 0 | P8: =COUNTIFS($B$2:$B$301,N8,$L$2:$L$301,">75") -> 0 | Q8: =TRIM(IF(O8>=2,"Cut lower-body accessories 25% next week. ","")&IF(P8>=2,"Sessions running long: trim the cut-first list.",""))
B9: =IF(A9="","",INT((A9-'Start here'!$C$5)/7)+1) | F9: =IF(COUNT(C9:E9)<3,"",SUM(C9:E9)) | G9: =IF(F9="","",IF(F9<=6,"Technique and mobility only",IF(F9<=8,"Main lift top set only; −1 set on every accessory; RPE cap 7","Train as planned"))) | K9: =IF(I9="","",IF(I9>=5,"Drop that pattern this week",IF(I9>=3,"Swap that exercise","OK"))) | N9: 8 | O9: =COUNTIFS($B$2:$B$301,N9,$H$2:$H$301,"Y") -> 0 | P9: =COUNTIFS($B$2:$B$301,N9,$L$2:$L$301,">75") -> 0 | Q9: =TRIM(IF(O9>=2,"Cut lower-body accessories 25% next week. ","")&IF(P9>=2,"Sessions running long: trim the cut-first list.",""))
B10: =IF(A10="","",INT((A10-'Start here'!$C$5)/7)+1) | F10: =IF(COUNT(C10:E10)<3,"",SUM(C10:E10)) | G10: =IF(F10="","",IF(F10<=6,"Technique and mobility only",IF(F10<=8,"Main lift top set only; −1 set on every accessory; RPE cap 7","Train as planned"))) | K10: =IF(I10="","",IF(I10>=5,"Drop that pattern this week",IF(I10>=3,"Swap that exercise","OK"))) | N10: 9 | O10: =COUNTIFS($B$2:$B$301,N10,$H$2:$H$301,"Y") -> 0 | P10: =COUNTIFS($B$2:$B$301,N10,$L$2:$L$301,">75") -> 0 | Q10: =TRIM(IF(O10>=2,"Cut lower-body accessories 25% next week. ","")&IF(P10>=2,"Sessions running long: trim the cut-first list.",""))
B11: =IF(A11="","",INT((A11-'Start here'!$C$5)/7)+1) | F11: =IF(COUNT(C11:E11)<3,"",SUM(C11:E11)) | G11: =IF(F11="","",IF(F11<=6,"Technique and mobility only",IF(F11<=8,"Main lift top set only; −1 set on every accessory; RPE cap 7","Train as planned"))) | K11: =IF(I11="","",IF(I11>=5,"Drop that pattern this week",IF(I11>=3,"Swap that exercise","OK"))) | N11: 10 | O11: =COUNTIFS($B$2:$B$301,N11,$H$2:$H$301,"Y") -> 0 | P11: =COUNTIFS($B$2:$B$301,N11,$L$2:$L$301,">75") -> 0 | Q11: =TRIM(IF(O11>=2,"Cut lower-body accessories 25% next week. ","")&IF(P11>=2,"Sessions running long: trim the cut-first list.",""))
B12: =IF(A12="","",INT((A12-'Start here'!$C$5)/7)+1) | F12: =IF(COUNT(C12:E12)<3,"",SUM(C12:E12)) | G12: =IF(F12="","",IF(F12<=6,"Technique and mobility only",IF(F12<=8,"Main lift top set only; −1 set on every accessory; RPE cap 7","Train as planned"))) | K12: =IF(I12="","",IF(I12>=5,"Drop that pattern this week",IF(I12>=3,"Swap that exercise","OK"))) | N12: 11 | O12: =COUNTIFS($B$2:$B$301,N12,$H$2:$H$301,"Y") -> 0 | P12: =COUNTIFS($B$2:$B$301,N12,$L$2:$L$301,">75") -> 0 | Q12: =TRIM(IF(O12>=2,"Cut lower-body accessories 25% next week. ","")&IF(P12>=2,"Sessions running long: trim the cut-first list.",""))
B13: =IF(A13="","",INT((A13-'Start here'!$C$5)/7)+1) | F13: =IF(COUNT(C13:E13)<3,"",SUM(C13:E13)) | G13: =IF(F13="","",IF(F13<=6,"Technique and mobility only",IF(F13<=8,"Main lift top set only; −1 set on every accessory; RPE cap 7","Train as planned"))) | K13: =IF(I13="","",IF(I13>=5,"Drop that pattern this week",IF(I13>=3,"Swap that exercise","OK"))) | N13: 12 | O13: =COUNTIFS($B$2:$B$301,N13,$H$2:$H$301,"Y") -> 0 | P13: =COUNTIFS($B$2:$B$301,N13,$L$2:$L$301,">75") -> 0 | Q13: =TRIM(IF(O13>=2,"Cut lower-body accessories 25% next week. ","")&IF(P13>=2,"Sessions running long: trim the cut-first list.",""))
B14: =IF(A14="","",INT((A14-'Start here'!$C$5)/7)+1) | F14: =IF(COUNT(C14:E14)<3,"",SUM(C14:E14)) | G14: =IF(F14="","",IF(F14<=6,"Technique and mobility only",IF(F14<=8,"Main lift top set only; −1 set on every accessory; RPE cap 7","Train as planned"))) | K14: =IF(I14="","",IF(I14>=5,"Drop that pattern this week",IF(I14>=3,"Swap that exercise","OK"))) | N14: 13 | O14: =COUNTIFS($B$2:$B$301,N14,$H$2:$H$301,"Y") -> 0 | P14: =COUNTIFS($B$2:$B$301,N14,$L$2:$L$301,">75") -> 0 | Q14: =TRIM(IF(O14>=2,"Cut lower-body accessories 25% next week. ","")&IF(P14>=2,"Sessions running long: trim the cut-first list.",""))
... B32: =IF(A32="","",INT((A32-'Start here'!$C$5)/7)+1) | F32: =IF(COUNT(C32:E32)<3,"",SUM(C32:E32)) | G32: =IF(F32="","",IF(F32<=6,"Technique and mobility only",IF(F32<=8,"Main lift top set only; −1 set on every accessory; RPE cap 7","Train as planned"))) | K32: =IF(I32="","",IF(I32>=5,"Drop that pattern this week",IF(I32>=3,"Swap that exercise","OK"))) | N32: 31 | O32: =COUNTIFS($B$2:$B$301,N32,$H$2:$H$301,"Y") -> 0 | P32: =COUNTIFS($B$2:$B$301,N32,$L$2:$L$301,">75") -> 0 | Q32: =TRIM(IF(O32>=2,"Cut lower-body accessories 25% next week. ","")&IF(P32>=2,"Sessions running long: trim the cut-first list.",""))
B33: =IF(A33="","",INT((A33-'Start here'!$C$5)/7)+1) | F33: =IF(COUNT(C33:E33)<3,"",SUM(C33:E33)) | G33: =IF(F33="","",IF(F33<=6,"Technique and mobility only",IF(F33<=8,"Main lift top set only; −1 set on every accessory; RPE cap 7","Train as planned"))) | K33: =IF(I33="","",IF(I33>=5,"Drop that pattern this week",IF(I33>=3,"Swap that exercise","OK")))
B34: =IF(A34="","",INT((A34-'Start here'!$C$5)/7)+1) | F34: =IF(COUNT(C34:E34)<3,"",SUM(C34:E34)) | G34: =IF(F34="","",IF(F34<=6,"Technique and mobility only",IF(F34<=8,"Main lift top set only; −1 set on every accessory; RPE cap 7","Train as planned"))) | K34: =IF(I34="","",IF(I34>=5,"Drop that pattern this week",IF(I34>=3,"Swap that exercise","OK")))
B35: =IF(A35="","",INT((A35-'Start here'!$C$5)/7)+1) | F35: =IF(COUNT(C35:E35)<3,"",SUM(C35:E35)) | G35: =IF(F35="","",IF(F35<=6,"Technique and mobility only",IF(F35<=8,"Main lift top set only; −1 set on every accessory; RPE cap 7","Train as planned"))) | K35: =IF(I35="","",IF(I35>=5,"Drop that pattern this week",IF(I35>=3,"Swap that exercise","OK")))
B36: =IF(A36="","",INT((A36-'Start here'!$C$5)/7)+1) | F36: =IF(COUNT(C36:E36)<3,"",SUM(C36:E36)) | G36: =IF(F36="","",IF(F36<=6,"Technique and mobility only",IF(F36<=8,"Main lift top set only; −1 set on every accessory; RPE cap 7","Train as planned"))) | K36: =IF(I36="","",IF(I36>=5,"Drop that pattern this week",IF(I36>=3,"Swap that exercise","OK")))
B37: =IF(A37="","",INT((A37-'Start here'!$C$5)/7)+1) | F37: =IF(COUNT(C37:E37)<3,"",SUM(C37:E37)) | G37: =IF(F37="","",IF(F37<=6,"Technique and mobility only",IF(F37<=8,"Main lift top set only; −1 set on every accessory; RPE cap 7","Train as planned"))) | K37: =IF(I37="","",IF(I37>=5,"Drop that pattern this week",IF(I37>=3,"Swap that exercise","OK")))
B38: =IF(A38="","",INT((A38-'Start here'!$C$5)/7)+1) | F38: =IF(COUNT(C38:E38)<3,"",SUM(C38:E38)) | G38: =IF(F38="","",IF(F38<=6,"Technique and mobility only",IF(F38<=8,"Main lift top set only; −1 set on every accessory; RPE cap 7","Train as planned"))) | K38: =IF(I38="","",IF(I38>=5,"Drop that pattern this week",IF(I38>=3,"Swap that exercise","OK")))
B39: =IF(A39="","",INT((A39-'Start here'!$C$5)/7)+1) | F39: =IF(COUNT(C39:E39)<3,"",SUM(C39:E39)) | G39: =IF(F39="","",IF(F39<=6,"Technique and mobility only",IF(F39<=8,"Main lift top set only; −1 set on every accessory; RPE cap 7","Train as planned"))) | K39: =IF(I39="","",IF(I39>=5,"Drop that pattern this week",IF(I39>=3,"Swap that exercise","OK")))
B40: =IF(A40="","",INT((A40-'Start here'!$C$5)/7)+1) | F40: =IF(COUNT(C40:E40)<3,"",SUM(C40:E40)) | G40: =IF(F40="","",IF(F40<=6,"Technique and mobility only",IF(F40<=8,"Main lift top set only; −1 set on every accessory; RPE cap 7","Train as planned"))) | K40: =IF(I40="","",IF(I40>=5,"Drop that pattern this week",IF(I40>=3,"Swap that exercise","OK")))
B41: =IF(A41="","",INT((A41-'Start here'!$C$5)/7)+1) | F41: =IF(COUNT(C41:E41)<3,"",SUM(C41:E41)) | G41: =IF(F41="","",IF(F41<=6,"Technique and mobility only",IF(F41<=8,"Main lift top set only; −1 set on every accessory; RPE cap 7","Train as planned"))) | K41: =IF(I41="","",IF(I41>=5,"Drop that pattern this week",IF(I41>=3,"Swap that exercise","OK")))
B42: =IF(A42="","",INT((A42-'Start here'!$C$5)/7)+1) | F42: =IF(COUNT(C42:E42)<3,"",SUM(C42:E42)) | G42: =IF(F42="","",IF(F42<=6,"Technique and mobility only",IF(F42<=8,"Main lift top set only; −1 set on every accessory; RPE cap 7","Train as planned"))) | K42: =IF(I42="","",IF(I42>=5,"Drop that pattern this week",IF(I42>=3,"Swap that exercise","OK")))
B43: =IF(A43="","",INT((A43-'Start here'!$C$5)/7)+1) | F43: =IF(COUNT(C43:E43)<3,"",SUM(C43:E43)) | G43: =IF(F43="","",IF(F43<=6,"Technique and mobility only",IF(F43<=8,"Main lift top set only; −1 set on every accessory; RPE cap 7","Train as planned"))) | K43: =IF(I43="","",IF(I43>=5,"Drop that pattern this week",IF(I43>=3,"Swap that exercise","OK")))
B44: =IF(A44="","",INT((A44-'Start here'!$C$5)/7)+1) | F44: =IF(COUNT(C44:E44)<3,"",SUM(C44:E44)) | G44: =IF(F44="","",IF(F44<=6,"Technique and mobility only",IF(F44<=8,"Main lift top set only; −1 set on every accessory; RPE cap 7","Train as planned"))) | K44: =IF(I44="","",IF(I44>=5,"Drop that pattern this week",IF(I44>=3,"Swap that exercise","OK")))
... B301: =IF(A301="","",INT((A301-'Start here'!$C$5)/7)+1) | F301: =IF(COUNT(C301:E301)<3,"",SUM(C301:E301)) | G301: =IF(F301="","",IF(F301<=6,"Technique and mobility only",IF(F301<=8,"Main lift top set only; −1 set on every accessory; RPE cap 7","Train as planned"))) | K301: =IF(I301="","",IF(I301>=5,"Drop that pattern this week",IF(I301>=3,"Swap that exercise","OK")))
A303: Grey row = example; overwrite it. Score before training; 'Kung fu felt flat' is about that night's class.

Sheet Tests
A1: Test | B1: How | C1: Unit | D1: Fixed load (kg) | E1: Block 1 wk 1 | F1: Block 1 wk 11 | G1: Change | H1: Block 2 wk 1 | I1: Block 2 wk 11 | J1: Change
A2: Neck flexion | B2: Harness, fixed load, slow reps to RIR 0 | C2: reps | G2: =IF(OR(E2="",F2="",E2=0),"",F2/E2-1) | J2: =IF(OR(F2="",I2="",F2=0),"",I2/F2-1)
A3: Neck extension | B3: Harness, fixed load, from flexed to neutral | C3: reps | G3: =IF(OR(E3="",F3="",E3=0),"",F3/E3-1) | J3: =IF(OR(F3="",I3="",F3=0),"",I3/F3-1)
A4: Neck lateral flexion L | B4: Harness, fixed load | C4: reps | G4: =IF(OR(E4="",F4="",E4=0),"",F4/E4-1) | J4: =IF(OR(F4="",I4="",F4=0),"",I4/F4-1)
A5: Neck lateral flexion R | B5: Harness, fixed load | C5: reps | G5: =IF(OR(E5="",F5="",E5=0),"",F5/E5-1) | J5: =IF(OR(F5="",I5="",F5=0),"",I5/F5-1)
A6: Hip IR (hip flexed) L/R worse side | B6: Seated cable, fixed load, controlled range | C6: reps | G6: =IF(OR(E6="",F6="",E6=0),"",F6/E6-1) | J6: =IF(OR(F6="",I6="",F6=0),"",I6/F6-1)
A7: Hip ER (hip flexed) L/R worse side | B7: Seated cable, fixed load | C7: reps | G7: =IF(OR(E7="",F7="",E7=0),"",F7/E7-1) | J7: =IF(OR(F7="",I7="",F7=0),"",I7/F7-1)
A8: Shoulder ER | B8: Cable at side, fixed load | C8: reps | G8: =IF(OR(E8="",F8="",E8=0),"",F8/E8-1) | J8: =IF(OR(F8="",I8="",F8=0),"",I8/F8-1)
A9: Pinch hold | B9: Two smooth plates, fixed total | C9: s | G9: =IF(OR(E9="",F9="",E9=0),"",F9/E9-1) | J9: =IF(OR(F9="",I9="",F9=0),"",I9/F9-1)
A10: Gripper | B10: Closes in one set | C10: reps | G10: =IF(OR(E10="",F10="",E10=0),"",F10/E10-1) | J10: =IF(OR(F10="",I10="",F10=0),"",I10/F10-1)
A11: Wrist radial deviation | B11: DB held at one end, fixed grip position | C11: reps | G11: =IF(OR(E11="",F11="",E11=0),"",F11/E11-1) | J11: =IF(OR(F11="",I11="",F11=0),"",I11/F11-1)
A12: Wrist ulnar deviation | B12: Same set-up | C12: reps | G12: =IF(OR(E12="",F12="",E12=0),"",F12/E12-1) | J12: =IF(OR(F12="",I12="",F12=0),"",I12/F12-1)
A13: Dorsiflexion | B13: Cable, fixed load | C13: reps | G13: =IF(OR(E13="",F13="",E13=0),"",F13/E13-1) | J13: =IF(OR(F13="",I13="",F13=0),"",I13/F13-1)
... A15: Toe flexion | B15: Towel curls with fixed weight | C15: reps | G15: =IF(OR(E15="",F15="",E15=0),"",F15/E15-1) | J15: =IF(OR(F15="",I15="",F15=0),"",I15/F15-1)
